<?xml version="1.0" ?>
<!-- =================================================================================== -->
<!-- |    This document was autogenerated by xacro from /home/developer/moveit_ws/src/antrop_arms/urdf/antrop_arms.xacro | -->
<!-- |    EDITING THIS FILE BY HAND IS NOT RECOMMENDED                                 | -->
<!-- =================================================================================== -->
<robot name="antrop_arms">
    <material name="silver">
        <color rgba="0.700 0.700 0.700 1.000" />
    </material>
    <transmission name="base_shoulder_left_joint_tran">
        <type>transmission_interface/SimpleTransmission</type>
        <joint name="base_shoulder_left_joint">
            <hardwareInterface>hardware_interface/EffortJointInterface</hardwareInterface>
        </joint>
        <actuator name="base_shoulder_left_joint_actr">
            <hardwareInterface>hardware_interface/EffortJointInterface</hardwareInterface>
            <mechanicalReduction>1</mechanicalReduction>
        </actuator>
    </transmission>
    <transmission name="shoulder_elbow_left_joint_tran">
        <type>transmission_interface/SimpleTransmission</type>
        <joint name="shoulder_elbow_left_joint">
            <hardwareInterface>hardware_interface/EffortJointInterface</hardwareInterface>
        </joint>
        <actuator name="shoulder_elbow_left_joint_actr">
            <hardwareInterface>hardware_interface/EffortJointInterface</hardwareInterface>
            <mechanicalReduction>1</mechanicalReduction>
        </actuator>
    </transmission>
    <transmission name="base_shoulder_right_joint_tran">
        <type>transmission_interface/SimpleTransmission</type>
        <joint name="base_shoulder_right_joint">
            <hardwareInterface>hardware_interface/EffortJointInterface</hardwareInterface>
        </joint>
        <actuator name="base_shoulder_right_joint_actr">
            <hardwareInterface>hardware_interface/EffortJointInterface</hardwareInterface>
            <mechanicalReduction>1</mechanicalReduction>
        </actuator>
    </transmission>
    <transmission name="shoulder_elbow_right_joint_tran">
        <type>transmission_interface/SimpleTransmission</type>
        <joint name="shoulder_elbow_right_joint">
            <hardwareInterface>hardware_interface/EffortJointInterface</hardwareInterface>
        </joint>
        <actuator name="shoulder_elbow_right_joint_actr">
            <hardwareInterface>hardware_interface/EffortJointInterface</hardwareInterface>
            <mechanicalReduction>1</mechanicalReduction>
        </actuator>
    </transmission>
    <transmission name="elbow_forearm_right_joint_tran">
        <type>transmission_interface/SimpleTransmission</type>
        <joint name="elbow_forearm_right_joint">
            <hardwareInterface>hardware_interface/EffortJointInterface</hardwareInterface>
        </joint>
        <actuator name="elbow_forearm_right_joint_actr">
            <hardwareInterface>hardware_interface/EffortJointInterface</hardwareInterface>
            <mechanicalReduction>1</mechanicalReduction>
        </actuator>
    </transmission>
    <transmission name="elbow_forearm_left_joint_tran">
        <type>transmission_interface/SimpleTransmission</type>
        <joint name="elbow_forearm_left_joint">
            <hardwareInterface>hardware_interface/EffortJointInterface</hardwareInterface>
        </joint>
        <actuator name="elbow_forearm_left_joint_actr">
            <hardwareInterface>hardware_interface/EffortJointInterface</hardwareInterface>
            <mechanicalReduction>1</mechanicalReduction>
        </actuator>
    </transmission>
    <gazebo>
        <plugin filename="libgazebo_ros_control.so" name="control">
            <robotNamespace>/antrop_arms</robotNamespace>
        </plugin>
        <plugin name="gazebo_ros_control">
            <robotNamespace>/</robotNamespace>
        </plugin>
    </gazebo>
    <gazebo reference="base_link">
        <material>Gazebo/Silver</material>
        <mu1>0.2</mu1>
        <mu2>0.2</mu2>
        <selfCollide>true</selfCollide>
        <gravity>true</gravity>
    </gazebo>
    <gazebo reference="Shoulder_Yaw_Structure_v1_1">
        <material>Gazebo/Silver</material>
        <mu1>0.2</mu1>
        <mu2>0.2</mu2>
        <selfCollide>true</selfCollide>
    </gazebo>
    <gazebo reference="Servo_Herkulex_v1_1">
        <material>Gazebo/Silver</material>
        <mu1>0.2</mu1>
        <mu2>0.2</mu2>
        <selfCollide>true</selfCollide>
    </gazebo>
    <gazebo reference="Shoulder_Yaw_Transmission_v1_1">
        <material>Gazebo/Silver</material>
        <mu1>0.2</mu1>
        <mu2>0.2</mu2>
        <selfCollide>true</selfCollide>
    </gazebo>
    <gazebo reference="elbow_left_link_1">
        <material>Gazebo/Silver</material>
        <mu1>0.2</mu1>
        <mu2>0.2</mu2>
        <selfCollide>true</selfCollide>
    </gazebo>
    <gazebo reference="Shoulder_Yaw_Structure_v1__1__1">
        <material>Gazebo/Silver</material>
        <mu1>0.2</mu1>
        <mu2>0.2</mu2>
        <selfCollide>true</selfCollide>
    </gazebo>
    <gazebo reference="Servo_Herkulex_v1__1__1">
        <material>Gazebo/Silver</material>
        <mu1>0.2</mu1>
        <mu2>0.2</mu2>
        <selfCollide>true</selfCollide>
    </gazebo>
    <gazebo reference="Shoulder_Yaw_Transmission_v1__1__1">
        <material>Gazebo/Silver</material>
        <mu1>0.2</mu1>
        <mu2>0.2</mu2>
        <selfCollide>true</selfCollide>
    </gazebo>
    <gazebo reference="elbow_right_link_1">
        <material>Gazebo/Silver</material>
        <mu1>0.2</mu1>
        <mu2>0.2</mu2>
        <selfCollide>true</selfCollide>
    </gazebo>
    <gazebo reference="shoulder_right_link_1">
        <material>Gazebo/Silver</material>
        <mu1>0.2</mu1>
        <mu2>0.2</mu2>
        <selfCollide>true</selfCollide>
    </gazebo>
    <gazebo reference="shoulder_left_link_1">
        <material>Gazebo/Silver</material>
        <mu1>0.2</mu1>
        <mu2>0.2</mu2>
        <selfCollide>true</selfCollide>
    </gazebo>
    <gazebo reference="forearm_left_link_1">
        <material>Gazebo/Silver</material>
        <mu1>0.2</mu1>
        <mu2>0.2</mu2>
        <selfCollide>true</selfCollide>
    </gazebo>
    <gazebo reference="forearm_right_link_1">
        <material>Gazebo/Silver</material>
        <mu1>0.2</mu1>
        <mu2>0.2</mu2>
        <selfCollide>true</selfCollide>
    </gazebo>
    <link name="world" />
    <link name="base_link">
        <inertial>
            <origin rpy="0 0 0" xyz="1.066898751021674e-15 6.668117193885462e-17 -0.0018137714290285523" />
            <mass value="17.13115280088791" />
            <inertia ixx="0.071673" ixy="0.0" ixz="0.0" iyy="0.032901" iyz="0.0" izz="0.085379" />
        </inertial>
        <visual>
            <origin rpy="0 0 0" xyz="0 0 0" />
            <geometry>
                <mesh filename="package://antrop_arms_description/meshes/base_link.stl" scale="0.001 0.001 0.001" />
            </geometry>
            <material name="silver" />
        </visual>
        <collision>
            <origin rpy="0 0 0" xyz="0 0 0" />
            <geometry>
                <mesh filename="package://antrop_arms_description/meshes/base_link.stl" scale="0.001 0.001 0.001" />
            </geometry>
        </collision>
    </link>
    <link name="Shoulder_Yaw_Structure_v1_1">
        <inertial>
            <origin rpy="0 0 0" xyz="-0.021135735062036764 -8.326672684688674e-16 -0.04093696874713262" />
            <mass value="0.13081573332382615" />
            <inertia ixx="9.8e-05" ixy="-0.0" ixz="1e-06" iyy="0.000152" iyz="0.0" izz="6.3e-05" />
        </inertial>
        <visual>
            <origin rpy="0 0 0" xyz="-0.021 -0.18 0.0" />
            <geometry>
                <mesh filename="package://antrop_arms_description/meshes/Shoulder_Yaw_Structure_v1_1.stl" scale="0.001 0.001 0.001" />
            </geometry>
            <material name="silver" />
        </visual>
        <collision>
            <origin rpy="0 0 0" xyz="-0.021 -0.18 0.0" />
            <geometry>
                <mesh filename="package://antrop_arms_description/meshes/Shoulder_Yaw_Structure_v1_1.stl" scale="0.001 0.001 0.001" />
            </geometry>
        </collision>
    </link>
    <link name="Servo_Herkulex_v1_1">
        <inertial>
            <origin rpy="0 0 0" xyz="-0.015296200031691265 -5.551115123125783e-17 -0.02073708217051337" />
            <mass value="0.5836410679799175" />
            <inertia ixx="0.00013" ixy="0.0" ixz="-2e-06" iyy="0.000221" iyz="0.0" izz="0.000207" />
        </inertial>
        <visual>
            <origin rpy="0 0 0" xyz="0.0 -0.18 0.075" />
            <geometry>
                <mesh filename="package://antrop_arms_description/meshes/Servo_Herkulex_v1_1.stl" scale="0.001 0.001 0.001" />
            </geometry>
            <material name="silver" />
        </visual>
        <collision>
            <origin rpy="0 0 0" xyz="0.0 -0.18 0.075" />
            <geometry>
                <mesh filename="package://antrop_arms_description/meshes/Servo_Herkulex_v1_1.stl" scale="0.001 0.001 0.001" />
            </geometry>
        </collision>
    </link>
    <link name="Shoulder_Yaw_Transmission_v1_1">
        <inertial>
            <origin rpy="0 0 0" xyz="-1.8166024240429124e-14 -5.551115123125783e-17 -0.023088428353467902" />
            <mass value="0.7529944150379378" />
            <inertia ixx="0.000272" ixy="-0.0" ixz="0.0" iyy="0.000272" iyz="-0.0" izz="0.000239" />
        </inertial>
        <visual>
            <origin rpy="0 0 0" xyz="0.0155 -0.18 0.115" />
            <geometry>
                <mesh filename="package://antrop_arms_description/meshes/Shoulder_Yaw_Transmission_v1_1.stl" scale="0.001 0.001 0.001" />
            </geometry>
            <material name="silver" />
        </visual>
        <collision>
            <origin rpy="0 0 0" xyz="0.0155 -0.18 0.115" />
            <geometry>
                <mesh filename="package://antrop_arms_description/meshes/Shoulder_Yaw_Transmission_v1_1.stl" scale="0.001 0.001 0.001" />
            </geometry>
        </collision>
    </link>
    <link name="elbow_left_link_1">
        <inertial>
            <origin rpy="0 0 0" xyz="-1.899869150889799e-14 -0.00021228541858173133 -0.11684928259378977" />
            <mass value="0.6214584962841803" />
            <inertia ixx="0.000538" ixy="0.0" ixz="0.0" iyy="0.000531" iyz="-3e-06" izz="0.000118" />
        </inertial>
        <visual>
            <origin rpy="0 0 0" xyz="0.0155 -0.18 0.163" />
            <geometry>
                <mesh filename="package://antrop_arms_description/meshes/elbow_left_link_1.stl" scale="0.001 0.001 0.001" />
            </geometry>
            <material name="silver" />
        </visual>
        <collision>
            <origin rpy="0 0 0" xyz="0.0155 -0.18 0.163" />
            <geometry>
                <mesh filename="package://antrop_arms_description/meshes/elbow_left_link_1.stl" scale="0.001 0.001 0.001" />
            </geometry>
        </collision>
    </link>
    <link name="Shoulder_Yaw_Structure_v1__1__1">
        <inertial>
            <origin rpy="0 0 0" xyz="-0.021135735062036733 -9.43689570931383e-16 -0.040936968747132534" />
            <mass value="0.13081573332382615" />
            <inertia ixx="9.8e-05" ixy="-0.0" ixz="1e-06" iyy="0.000152" iyz="0.0" izz="6.3e-05" />
        </inertial>
        <visual>
            <origin rpy="0 0 0" xyz="-0.021 0.18 0.0" />
            <geometry>
                <mesh filename="package://antrop_arms_description/meshes/Shoulder_Yaw_Structure_v1__1__1.stl" scale="0.001 0.001 0.001" />
            </geometry>
            <material name="silver" />
        </visual>
        <collision>
            <origin rpy="0 0 0" xyz="-0.021 0.18 0.0" />
            <geometry>
                <mesh filename="package://antrop_arms_description/meshes/Shoulder_Yaw_Structure_v1__1__1.stl" scale="0.001 0.001 0.001" />
            </geometry>
        </collision>
    </link>
    <link name="Servo_Herkulex_v1__1__1">
        <inertial>
            <origin rpy="0 0 0" xyz="-0.015296200031691375 1.6653345369377348e-16 -0.020737082170513232" />
            <mass value="0.5836410679799175" />
            <inertia ixx="0.00013" ixy="0.0" ixz="-2e-06" iyy="0.000221" iyz="0.0" izz="0.000207" />
        </inertial>
        <visual>
            <origin rpy="0 0 0" xyz="0.0 0.18 0.075" />
            <geometry>
                <mesh filename="package://antrop_arms_description/meshes/Servo_Herkulex_v1__1__1.stl" scale="0.001 0.001 0.001" />
            </geometry>
            <material name="silver" />
        </visual>
        <collision>
            <origin rpy="0 0 0" xyz="0.0 0.18 0.075" />
            <geometry>
                <mesh filename="package://antrop_arms_description/meshes/Servo_Herkulex_v1__1__1.stl" scale="0.001 0.001 0.001" />
            </geometry>
        </collision>
    </link>
    <link name="Shoulder_Yaw_Transmission_v1__1__1">
        <inertial>
            <origin rpy="0 0 0" xyz="-1.8197249262996706e-14 1.942890293094024e-16 -0.023088428353467597" />
            <mass value="0.7529944150379378" />
            <inertia ixx="0.000272" ixy="-0.0" ixz="0.0" iyy="0.000272" iyz="0.0" izz="0.000239" />
        </inertial>
        <visual>
            <origin rpy="0 0 0" xyz="0.0155 0.18 0.115" />
            <geometry>
                <mesh filename="package://antrop_arms_description/meshes/Shoulder_Yaw_Transmission_v1__1__1.stl" scale="0.001 0.001 0.001" />
            </geometry>
            <material name="silver" />
        </visual>
        <collision>
            <origin rpy="0 0 0" xyz="0.0155 0.18 0.115" />
            <geometry>
                <mesh filename="package://antrop_arms_description/meshes/Shoulder_Yaw_Transmission_v1__1__1.stl" scale="0.001 0.001 0.001" />
            </geometry>
        </collision>
    </link>
    <link name="elbow_right_link_1">
        <inertial>
            <origin rpy="0 0 0" xyz="-1.675569405445998e-14 0.0002122854185845624 -0.11684928259381297" />
            <mass value="0.6214584962841804" />
            <inertia ixx="0.000538" ixy="-0.0" ixz="0.0" iyy="0.000531" iyz="3e-06" izz="0.000118" />
        </inertial>
        <visual>
            <origin rpy="0 0 0" xyz="0.0155 0.18 0.163" />
            <geometry>
                <mesh filename="package://antrop_arms_description/meshes/elbow_right_link_1.stl" scale="0.001 0.001 0.001" />
            </geometry>
            <material name="silver" />
        </visual>
        <collision>
            <origin rpy="0 0 0" xyz="0.0155 0.18 0.163" />
            <geometry>
                <mesh filename="package://antrop_arms_description/meshes/elbow_right_link_1.stl" scale="0.001 0.001 0.001" />
            </geometry>
        </collision>
    </link>
    <link name="shoulder_right_link_1">
        <inertial>
            <origin rpy="0 0 0" xyz="-0.0002500317321433487 -0.03591809092030432 -0.013543028885077014" />
            <mass value="0.6591423872621155" />
            <inertia ixx="0.000324" ixy="9e-06" ixz="2e-06" iyy="0.000242" iyz="-3.6e-05" izz="0.000235" />
        </inertial>
        <visual>
            <origin rpy="0 0 0" xyz="0.0 0.14 -0.0" />
            <geometry>
                <mesh filename="package://antrop_arms_description/meshes/shoulder_right_link_1.stl" scale="0.001 0.001 0.001" />
            </geometry>
            <material name="silver" />
        </visual>
        <collision>
            <origin rpy="0 0 0" xyz="0.0 0.14 -0.0" />
            <geometry>
                <mesh filename="package://antrop_arms_description/meshes/shoulder_right_link_1.stl" scale="0.001 0.001 0.001" />
            </geometry>
        </collision>
    </link>
    <link name="shoulder_left_link_1">
        <inertial>
            <origin rpy="0 0 0" xyz="-0.0002500317321533693 0.035918090920304124 -0.013543028885077059" />
            <mass value="0.6591423872621155" />
            <inertia ixx="0.000324" ixy="-9e-06" ixz="2e-06" iyy="0.000242" iyz="3.6e-05" izz="0.000235" />
        </inertial>
        <visual>
            <origin rpy="0 0 0" xyz="0.0 -0.14 -0.0" />
            <geometry>
                <mesh filename="package://antrop_arms_description/meshes/shoulder_left_link_1.stl" scale="0.001 0.001 0.001" />
            </geometry>
            <material name="silver" />
        </visual>
        <collision>
            <origin rpy="0 0 0" xyz="0.0 -0.14 -0.0" />
            <geometry>
                <mesh filename="package://antrop_arms_description/meshes/shoulder_left_link_1.stl" scale="0.001 0.001 0.001" />
            </geometry>
        </collision>
    </link>
    <link name="forearm_left_link_1">
        <inertial>
            <origin rpy="0 0 0" xyz="-2.4015511801422917e-14 -0.020000000000116203 -0.14499270392199487" />
            <mass value="0.20799291557495453" />
            <inertia ixx="0.001901" ixy="-0.0" ixz="-0.0" iyy="0.001879" iyz="0.0" izz="3.1e-05" />
        </inertial>
        <visual>
            <origin rpy="0 0 0" xyz="0.0155 0.16 0.3025" />
            <geometry>
                <mesh filename="package://antrop_arms_description/meshes/forearm_left_link_1.stl" scale="0.001 0.001 0.001" />
            </geometry>
            <material name="silver" />
        </visual>
        <collision>
            <origin rpy="0 0 0" xyz="0.0155 0.16 0.3025" />
            <geometry>
                <mesh filename="package://antrop_arms_description/meshes/forearm_left_link_1.stl" scale="0.001 0.001 0.001" />
            </geometry>
        </collision>
    </link>
    <link name="forearm_right_link_1">
        <inertial>
            <origin rpy="0 0 0" xyz="-2.80782341821606e-14 -0.020000000000115925 -0.14499270392199565" />
            <mass value="0.20799291557495453" />
            <inertia ixx="0.001901" ixy="-0.0" ixz="-0.0" iyy="0.001879" iyz="0.0" izz="3.1e-05" />
        </inertial>
        <visual>
            <origin rpy="0 0 0" xyz="0.0155 -0.2 0.3025" />
            <geometry>
                <mesh filename="package://antrop_arms_description/meshes/forearm_right_link_1.stl" scale="0.001 0.001 0.001" />
            </geometry>
            <material name="silver" />
        </visual>
        <collision>
            <origin rpy="0 0 0" xyz="0.0155 -0.2 0.3025" />
            <geometry>
                <mesh filename="package://antrop_arms_description/meshes/forearm_right_link_1.stl" scale="0.001 0.001 0.001" />
            </geometry>
        </collision>
    </link>
    <joint name="base_shoulder_left_joint" type="revolute">
        <origin rpy="0 0 0" xyz="0.021 0.04 -0.0" />
        <parent link="shoulder_left_link_1" />
        <child link="Shoulder_Yaw_Structure_v1_1" />
        <axis xyz="1.0 -0.0 0.0" />
        <limit effort="20.1" lower="-1.5708" upper="1.5708" velocity="2" />
    </joint>
    <joint name="Rigid3" type="fixed">
        <origin rpy="0 0 0" xyz="-0.021 0.0 -0.075" />
        <parent link="Shoulder_Yaw_Structure_v1_1" />
        <child link="Servo_Herkulex_v1_1" />
    </joint>
    <joint name="Rigid5" type="fixed">
        <origin rpy="0 0 0" xyz="-0.0155 0.0 -0.04" />
        <parent link="Servo_Herkulex_v1_1" />
        <child link="Shoulder_Yaw_Transmission_v1_1" />
    </joint>
    <joint name="shoulder_elbow_left_joint" type="revolute">
        <origin rpy="0 0 0" xyz="0.0 0.0 -0.048" />
        <parent link="Shoulder_Yaw_Transmission_v1_1" />
        <child link="elbow_left_link_1" />
        <axis xyz="0.0 0.0 1.0" />
        <limit effort="20.1" lower="-1.5708" upper="1.5708" velocity="2" />
    </joint>
    <joint name="base_shoulder_right_joint" type="revolute">
        <origin rpy="0 0 0" xyz="0.021 -0.04 -0.0" />
        <parent link="shoulder_right_link_1" />
        <child link="Shoulder_Yaw_Structure_v1__1__1" />
        <axis xyz="1 0 0" />
        <limit effort="20.1" lower="-1.5708" upper="1.5708" velocity="2" />
    </joint>
    <joint name="Rigid9" type="fixed">
        <origin rpy="0 0 0" xyz="-0.021 0.0 -0.075" />
        <parent link="Shoulder_Yaw_Structure_v1__1__1" />
        <child link="Servo_Herkulex_v1__1__1" />
    </joint>
    <joint name="Rigid10" type="fixed">
        <origin rpy="0 0 0" xyz="-0.0155 0.0 -0.04" />
        <parent link="Servo_Herkulex_v1__1__1" />
        <child link="Shoulder_Yaw_Transmission_v1__1__1" />
    </joint>
    <joint name="shoulder_elbow_right_joint" type="revolute">
        <origin rpy="0 0 0" xyz="0.0 0.0 -0.048" />
        <parent link="Shoulder_Yaw_Transmission_v1__1__1" />
        <child link="elbow_right_link_1" />
        <axis xyz="0.0 -0.0 1.0" />
        <limit effort="20.1" lower="-1.5708" upper="1.5708" velocity="2" />
    </joint>
    <joint name="base_shoulder_right_fixed_joint" type="fixed">
        <origin rpy="0 0 0" xyz="0.0 -0.14 0.0" />
        <parent link="base_link" />
        <child link="shoulder_right_link_1" />
    </joint>
    <joint name="base_shoulder_left_fixed_joint" type="fixed">
        <origin rpy="0 0 0" xyz="0.0 0.14 0.0" />
        <parent link="base_link" />
        <child link="shoulder_left_link_1" />
    </joint>
    <joint name="elbow_forearm_right_joint" type="revolute">
        <origin rpy="0 0 0" xyz="0.0 0.02 -0.1395" />
        <limit effort="20.1" lower="-2.35619" upper="2.35619" velocity="2" />
        <axis xyz="0 1 0" />
        <parent link="elbow_right_link_1" />
        <child link="forearm_right_link_1" />
    </joint>
    <joint name="elbow_forearm_left_joint" type="revolute">
        <origin rpy="0 0 0" xyz="0.0 0.02 -0.1395" />
        <limit effort="20.1" lower="-2.35619" upper="2.35619" velocity="2" />
        <parent link="elbow_left_link_1" />
        <axis xyz="0 1 0" />
        <child link="forearm_left_link_1" />
    </joint>
    <joint name="float_base_link" type="fixed">
        <origin rpy="0 0 0" xyz="0 0 1.5" />
        <parent link="world" />
        <child link="base_link" />
    </joint>
</robot>

